[17/09/2017 22:10] ERROR red load_cogs 573: You need to run `pip3 install youtube_dl`
Traceback (most recent call last):
  File "red.py", line 570, in load_cogs
    owner_cog._load_cog(extension)
  File "/home/peyrin/Desktop/Red-DiscordBot/cogs/owner.py", line 947, in _load_cog
    self.bot.load_extension(mod_obj.__name__)
  File "/home/peyrin/anaconda3/lib/python3.6/site-packages/discord/ext/commands/bot.py", line 738, in load_extension
    lib.setup(self)
  File "/home/peyrin/Desktop/Red-DiscordBot/cogs/audio.py", line 2369, in setup
    raise RuntimeError("You need to run `pip3 install youtube_dl`")
RuntimeError: You need to run `pip3 install youtube_dl`
[17/09/2017 22:10] ERROR red load_cogs 573: Command rps is already registered.
Traceback (most recent call last):
  File "red.py", line 570, in load_cogs
    owner_cog._load_cog(extension)
  File "/home/peyrin/Desktop/Red-DiscordBot/cogs/owner.py", line 947, in _load_cog
    self.bot.load_extension(mod_obj.__name__)
  File "/home/peyrin/anaconda3/lib/python3.6/site-packages/discord/ext/commands/bot.py", line 738, in load_extension
    lib.setup(self)
  File "/home/peyrin/Desktop/Red-DiscordBot/cogs/general.py", line 434, in setup
    bot.add_cog(n)
  File "/home/peyrin/anaconda3/lib/python3.6/site-packages/discord/ext/commands/bot.py", line 655, in add_cog
    self.add_command(member)
  File "/home/peyrin/anaconda3/lib/python3.6/site-packages/discord/ext/commands/core.py", line 487, in add_command
    raise discord.ClientException('Command {0.name} is already registered.'.format(command))
discord.errors.ClientException: Command rps is already registered.
[17/09/2017 22:10] ERROR red load_cogs 573: You need the imgurpython module to use this.
pip3 install imgurpython
Traceback (most recent call last):
  File "red.py", line 570, in load_cogs
    owner_cog._load_cog(extension)
  File "/home/peyrin/Desktop/Red-DiscordBot/cogs/owner.py", line 947, in _load_cog
    self.bot.load_extension(mod_obj.__name__)
  File "/home/peyrin/anaconda3/lib/python3.6/site-packages/discord/ext/commands/bot.py", line 738, in load_extension
    lib.setup(self)
  File "/home/peyrin/Desktop/Red-DiscordBot/cogs/image.py", line 165, in setup
    raise RuntimeError("You need the imgurpython module to use this.\n"
RuntimeError: You need the imgurpython module to use this.
pip3 install imgurpython
[17/09/2017 22:25] ERROR owner load 73: Command rps is already registered.
Traceback (most recent call last):
  File "/home/peyrin/Desktop/Red-DiscordBot/cogs/owner.py", line 64, in load
    self._load_cog(module)
  File "/home/peyrin/Desktop/Red-DiscordBot/cogs/owner.py", line 947, in _load_cog
    self.bot.load_extension(mod_obj.__name__)
  File "lib/discord/ext/commands/bot.py", line 738, in load_extension
    lib.setup(self)
  File "/home/peyrin/Desktop/Red-DiscordBot/cogs/general.py", line 434, in setup
    bot.add_cog(n)
  File "lib/discord/ext/commands/bot.py", line 655, in add_cog
    self.add_command(member)
  File "lib/discord/ext/commands/core.py", line 487, in add_command
    raise discord.ClientException('Command {0.name} is already registered.'.format(command))
discord.errors.ClientException: Command rps is already registered.
[17/09/2017 22:43] ERROR red load_cogs 573: ('invalid syntax', ('/home/peyrin/Desktop/Red-DiscordBot/cogs/general.py', 180, 34, '    async def whodunit(self, ctx)\n'))
Traceback (most recent call last):
  File "/home/peyrin/Desktop/Red-DiscordBot/cogs/owner.py", line 945, in _load_cog
    mod_obj = importlib.import_module(cogname)
  File "/home/peyrin/anaconda3/lib/python3.6/importlib/__init__.py", line 126, in import_module
    return _bootstrap._gcd_import(name[level:], package, level)
  File "<frozen importlib._bootstrap>", line 978, in _gcd_import
  File "<frozen importlib._bootstrap>", line 961, in _find_and_load
  File "<frozen importlib._bootstrap>", line 950, in _find_and_load_unlocked
  File "<frozen importlib._bootstrap>", line 655, in _load_unlocked
  File "<frozen importlib._bootstrap_external>", line 674, in exec_module
  File "<frozen importlib._bootstrap_external>", line 781, in get_code
  File "<frozen importlib._bootstrap_external>", line 741, in source_to_code
  File "<frozen importlib._bootstrap>", line 205, in _call_with_frames_removed
  File "/home/peyrin/Desktop/Red-DiscordBot/cogs/general.py", line 180
    async def whodunit(self, ctx)
                                ^
SyntaxError: invalid syntax

During handling of the above exception, another exception occurred:

Traceback (most recent call last):
  File "red.py", line 570, in load_cogs
    owner_cog._load_cog(extension)
  File "/home/peyrin/Desktop/Red-DiscordBot/cogs/owner.py", line 949, in _load_cog
    raise CogLoadError(*e.args)
cogs.owner.CogLoadError: ('invalid syntax', ('/home/peyrin/Desktop/Red-DiscordBot/cogs/general.py', 180, 34, '    async def whodunit(self, ctx)\n'))
[17/09/2017 22:43] ERROR owner load 73: name 'pass_context_True' is not defined
Traceback (most recent call last):
  File "/home/peyrin/Desktop/Red-DiscordBot/cogs/owner.py", line 64, in load
    self._load_cog(module)
  File "/home/peyrin/Desktop/Red-DiscordBot/cogs/owner.py", line 945, in _load_cog
    mod_obj = importlib.import_module(cogname)
  File "/home/peyrin/anaconda3/lib/python3.6/importlib/__init__.py", line 126, in import_module
    return _bootstrap._gcd_import(name[level:], package, level)
  File "<frozen importlib._bootstrap>", line 978, in _gcd_import
  File "<frozen importlib._bootstrap>", line 961, in _find_and_load
  File "<frozen importlib._bootstrap>", line 950, in _find_and_load_unlocked
  File "<frozen importlib._bootstrap>", line 655, in _load_unlocked
  File "<frozen importlib._bootstrap_external>", line 678, in exec_module
  File "<frozen importlib._bootstrap>", line 205, in _call_with_frames_removed
  File "/home/peyrin/Desktop/Red-DiscordBot/cogs/general.py", line 36, in <module>
    class General:
  File "/home/peyrin/Desktop/Red-DiscordBot/cogs/general.py", line 179, in General
    @commands.command(pass_context_True, no_pm=True)
NameError: name 'pass_context_True' is not defined
[17/09/2017 22:44] ERROR red on_command_error 369: Exception in command 'whodunit'
Traceback (most recent call last):
  File "lib/discord/ext/commands/core.py", line 50, in wrapped
    ret = yield from coro(*args, **kwargs)
  File "/home/peyrin/Desktop/Red-DiscordBot/cogs/general.py", line 184, in whodunit
    await self.bot.say("It was " + choice(member_list) + "!!!")
  File "/home/peyrin/anaconda3/lib/python3.6/random.py", line 258, in choice
    return seq[i]
TypeError: 'dict_values' object does not support indexing
[17/09/2017 22:45] ERROR red on_command_error 369: Exception in command 'whodunit'
Traceback (most recent call last):
  File "lib/discord/ext/commands/core.py", line 50, in wrapped
    ret = yield from coro(*args, **kwargs)
  File "/home/peyrin/Desktop/Red-DiscordBot/cogs/general.py", line 184, in whodunit
    await self.bot.say("It was " + choice(member_list) + "!!!")
TypeError: must be str, not Member
[17/09/2017 22:46] ERROR red on_command_error 369: Exception in command 'whodunit'
Traceback (most recent call last):
  File "lib/discord/ext/commands/core.py", line 50, in wrapped
    ret = yield from coro(*args, **kwargs)
  File "/home/peyrin/Desktop/Red-DiscordBot/cogs/general.py", line 184, in whodunit
    await self.bot.say("It was " + choice(member_list).nick + "!!!")
TypeError: must be str, not NoneType
[17/09/2017 22:50] ERROR red load_cogs 573: name 'ctx' is not defined
Traceback (most recent call last):
  File "red.py", line 570, in load_cogs
    owner_cog._load_cog(extension)
  File "/home/peyrin/Desktop/Red-DiscordBot/cogs/owner.py", line 947, in _load_cog
    self.bot.load_extension(mod_obj.__name__)
  File "lib/discord/ext/commands/bot.py", line 738, in load_extension
    lib.setup(self)
  File "/home/peyrin/Desktop/Red-DiscordBot/cogs/general.py", line 439, in setup
    n = General(bot)
  File "/home/peyrin/Desktop/Red-DiscordBot/cogs/general.py", line 47, in __init__
    server = ctx.message.server
NameError: name 'ctx' is not defined
[17/09/2017 23:35] ERROR red on_command_error 369: Exception in command 'colors'
Traceback (most recent call last):
  File "lib/discord/ext/commands/core.py", line 50, in wrapped
    ret = yield from coro(*args, **kwargs)
  File "/home/peyrin/Desktop/Red-DiscordBot/cogs/mod.py", line 174, in colors
    role_list = list(server.roles.name)
AttributeError: 'list' object has no attribute 'name'
[17/09/2017 23:36] ERROR red load_cogs 573: ('invalid syntax', ('/home/peyrin/Desktop/Red-DiscordBot/cogs/mod.py', 175, 30, '        role_list = e.name for e in role_list\n'))
Traceback (most recent call last):
  File "/home/peyrin/Desktop/Red-DiscordBot/cogs/owner.py", line 945, in _load_cog
    mod_obj = importlib.import_module(cogname)
  File "/home/peyrin/anaconda3/lib/python3.6/importlib/__init__.py", line 126, in import_module
    return _bootstrap._gcd_import(name[level:], package, level)
  File "<frozen importlib._bootstrap>", line 978, in _gcd_import
  File "<frozen importlib._bootstrap>", line 961, in _find_and_load
  File "<frozen importlib._bootstrap>", line 950, in _find_and_load_unlocked
  File "<frozen importlib._bootstrap>", line 655, in _load_unlocked
  File "<frozen importlib._bootstrap_external>", line 674, in exec_module
  File "<frozen importlib._bootstrap_external>", line 781, in get_code
  File "<frozen importlib._bootstrap_external>", line 741, in source_to_code
  File "<frozen importlib._bootstrap>", line 205, in _call_with_frames_removed
  File "/home/peyrin/Desktop/Red-DiscordBot/cogs/mod.py", line 175
    role_list = e.name for e in role_list
                         ^
SyntaxError: invalid syntax

During handling of the above exception, another exception occurred:

Traceback (most recent call last):
  File "red.py", line 570, in load_cogs
    owner_cog._load_cog(extension)
  File "/home/peyrin/Desktop/Red-DiscordBot/cogs/owner.py", line 949, in _load_cog
    raise CogLoadError(*e.args)
cogs.owner.CogLoadError: ('invalid syntax', ('/home/peyrin/Desktop/Red-DiscordBot/cogs/mod.py', 175, 30, '        role_list = e.name for e in role_list\n'))
[17/09/2017 23:37] ERROR red on_command_error 369: Exception in command 'colors'
Traceback (most recent call last):
  File "lib/discord/ext/commands/core.py", line 50, in wrapped
    ret = yield from coro(*args, **kwargs)
  File "/home/peyrin/Desktop/Red-DiscordBot/cogs/mod.py", line 177, in colors
    role_list.remove('overlord').remove('Edmund').remove('Bots').remove('can mod people')
ValueError: list.remove(x): x not in list
[17/09/2017 23:38] ERROR red load_cogs 573: ('invalid syntax', ('/home/peyrin/Desktop/Red-DiscordBot/cogs/mod.py', 180, 15, "        message = ', '.join(e for e in role_list)\n"))
Traceback (most recent call last):
  File "/home/peyrin/Desktop/Red-DiscordBot/cogs/owner.py", line 945, in _load_cog
    mod_obj = importlib.import_module(cogname)
  File "/home/peyrin/anaconda3/lib/python3.6/importlib/__init__.py", line 126, in import_module
    return _bootstrap._gcd_import(name[level:], package, level)
  File "<frozen importlib._bootstrap>", line 978, in _gcd_import
  File "<frozen importlib._bootstrap>", line 961, in _find_and_load
  File "<frozen importlib._bootstrap>", line 950, in _find_and_load_unlocked
  File "<frozen importlib._bootstrap>", line 655, in _load_unlocked
  File "<frozen importlib._bootstrap_external>", line 674, in exec_module
  File "<frozen importlib._bootstrap_external>", line 781, in get_code
  File "<frozen importlib._bootstrap_external>", line 741, in source_to_code
  File "<frozen importlib._bootstrap>", line 205, in _call_with_frames_removed
  File "/home/peyrin/Desktop/Red-DiscordBot/cogs/mod.py", line 180
    message = ', '.join(e for e in role_list)
          ^
SyntaxError: invalid syntax

During handling of the above exception, another exception occurred:

Traceback (most recent call last):
  File "red.py", line 570, in load_cogs
    owner_cog._load_cog(extension)
  File "/home/peyrin/Desktop/Red-DiscordBot/cogs/owner.py", line 949, in _load_cog
    raise CogLoadError(*e.args)
cogs.owner.CogLoadError: ('invalid syntax', ('/home/peyrin/Desktop/Red-DiscordBot/cogs/mod.py', 180, 15, "        message = ', '.join(e for e in role_list)\n"))
[17/09/2017 23:42] ERROR owner load 68: ('invalid syntax', ('/home/peyrin/Desktop/Red-DiscordBot/cogs/mod.py', 180, 15, "        message = ''\n"))
Traceback (most recent call last):
  File "/home/peyrin/Desktop/Red-DiscordBot/cogs/owner.py", line 945, in _load_cog
    mod_obj = importlib.import_module(cogname)
  File "/home/peyrin/anaconda3/lib/python3.6/importlib/__init__.py", line 126, in import_module
    return _bootstrap._gcd_import(name[level:], package, level)
  File "<frozen importlib._bootstrap>", line 978, in _gcd_import
  File "<frozen importlib._bootstrap>", line 961, in _find_and_load
  File "<frozen importlib._bootstrap>", line 950, in _find_and_load_unlocked
  File "<frozen importlib._bootstrap>", line 655, in _load_unlocked
  File "<frozen importlib._bootstrap_external>", line 674, in exec_module
  File "<frozen importlib._bootstrap_external>", line 781, in get_code
  File "<frozen importlib._bootstrap_external>", line 741, in source_to_code
  File "<frozen importlib._bootstrap>", line 205, in _call_with_frames_removed
  File "/home/peyrin/Desktop/Red-DiscordBot/cogs/mod.py", line 180
    message = ''
          ^
SyntaxError: invalid syntax

During handling of the above exception, another exception occurred:

Traceback (most recent call last):
  File "/home/peyrin/Desktop/Red-DiscordBot/cogs/owner.py", line 64, in load
    self._load_cog(module)
  File "/home/peyrin/Desktop/Red-DiscordBot/cogs/owner.py", line 949, in _load_cog
    raise CogLoadError(*e.args)
cogs.owner.CogLoadError: ('invalid syntax', ('/home/peyrin/Desktop/Red-DiscordBot/cogs/mod.py', 180, 15, "        message = ''\n"))
[17/09/2017 23:43] ERROR red on_command_error 369: Exception in command 'colors'
Traceback (most recent call last):
  File "lib/discord/ext/commands/core.py", line 50, in wrapped
    ret = yield from coro(*args, **kwargs)
  File "/home/peyrin/Desktop/Red-DiscordBot/cogs/mod.py", line 181, in colors
    message.join(e)
TypeError: can only join an iterable
[17/09/2017 23:44] ERROR red on_command_error 369: Exception in command 'colors'
Traceback (most recent call last):
  File "lib/discord/ext/commands/core.py", line 50, in wrapped
    ret = yield from coro(*args, **kwargs)
  File "/home/peyrin/Desktop/Red-DiscordBot/cogs/mod.py", line 180, in colors
    message.join(',', role_list)
TypeError: join() takes exactly one argument (2 given)
[17/09/2017 23:46] ERROR red on_command_error 369: Exception in command 'colors'
Traceback (most recent call last):
  File "lib/discord/ext/commands/core.py", line 50, in wrapped
    ret = yield from coro(*args, **kwargs)
  File "/home/peyrin/Desktop/Red-DiscordBot/cogs/mod.py", line 179, in colors
    await self.bot.say(','.join(role_list))
TypeError: sequence item 0: expected str instance, Role found
[17/09/2017 23:46] ERROR red on_command_error 369: Exception in command 'colors'
Traceback (most recent call last):
  File "lib/discord/ext/commands/core.py", line 50, in wrapped
    ret = yield from coro(*args, **kwargs)
  File "/home/peyrin/Desktop/Red-DiscordBot/cogs/mod.py", line 177, in colors
    await self.bot.say(','.join(role_list))
  File "lib/discord/ext/commands/bot.py", line 309, in _augmented_msg
    msg = yield from coro
  File "red.py", line 92, in send_message
    return await super().send_message(*args, **kwargs)
  File "lib/discord/client.py", line 1152, in send_message
    data = yield from self.http.send_message(channel_id, content, guild_id=guild_id, tts=tts, embed=embed)
  File "lib/discord/http.py", line 200, in request
    raise HTTPException(r, data)
discord.errors.HTTPException: BAD REQUEST (status code: 400)
[17/09/2017 23:47] ERROR red on_command_error 369: Exception in command 'colors'
Traceback (most recent call last):
  File "lib/discord/ext/commands/core.py", line 50, in wrapped
    ret = yield from coro(*args, **kwargs)
  File "/home/peyrin/Desktop/Red-DiscordBot/cogs/mod.py", line 177, in colors
    await self.bot.say(','.join(role_list))
  File "lib/discord/ext/commands/bot.py", line 309, in _augmented_msg
    msg = yield from coro
  File "red.py", line 92, in send_message
    return await super().send_message(*args, **kwargs)
  File "lib/discord/client.py", line 1152, in send_message
    data = yield from self.http.send_message(channel_id, content, guild_id=guild_id, tts=tts, embed=embed)
  File "lib/discord/http.py", line 200, in request
    raise HTTPException(r, data)
discord.errors.HTTPException: BAD REQUEST (status code: 400)
[17/09/2017 23:48] ERROR red on_command_error 369: Exception in command 'colors'
Traceback (most recent call last):
  File "lib/discord/ext/commands/core.py", line 50, in wrapped
    ret = yield from coro(*args, **kwargs)
  File "/home/peyrin/Desktop/Red-DiscordBot/cogs/mod.py", line 179, in colors
    await self.bot.say(','.join(role_list))
TypeError: sequence item 0: expected str instance, Role found
[17/09/2017 23:52] ERROR red on_command_error 369: Exception in command 'colors'
Traceback (most recent call last):
  File "lib/discord/ext/commands/core.py", line 50, in wrapped
    ret = yield from coro(*args, **kwargs)
  File "/home/peyrin/Desktop/Red-DiscordBot/cogs/mod.py", line 178, in colors
    role_strings.remove('overlord').remove('Edmund').remove('Bots').remove('can mod people')
AttributeError: 'NoneType' object has no attribute 'remove'
[17/09/2017 23:57] ERROR red on_command_error 369: Exception in command 'colors'
Traceback (most recent call last):
  File "lib/discord/ext/commands/core.py", line 50, in wrapped
    ret = yield from coro(*args, **kwargs)
  File "/home/peyrin/Desktop/Red-DiscordBot/cogs/mod.py", line 176, in colors
    reverse(role_list)
NameError: name 'reverse' is not defined
[18/09/2017 00:37] ERROR red load_cogs 573: ('expected an indented block', ('/home/peyrin/Desktop/Red-DiscordBot/cogs/remindme.py', 71, 26, '                    except (discord.errors.Forbidden, discord.errors.NotFound):\n'))
Traceback (most recent call last):
  File "/home/peyrin/Desktop/Red-DiscordBot/cogs/owner.py", line 945, in _load_cog
    mod_obj = importlib.import_module(cogname)
  File "/home/peyrin/anaconda3/lib/python3.6/importlib/__init__.py", line 126, in import_module
    return _bootstrap._gcd_import(name[level:], package, level)
  File "<frozen importlib._bootstrap>", line 978, in _gcd_import
  File "<frozen importlib._bootstrap>", line 961, in _find_and_load
  File "<frozen importlib._bootstrap>", line 950, in _find_and_load_unlocked
  File "<frozen importlib._bootstrap>", line 655, in _load_unlocked
  File "<frozen importlib._bootstrap_external>", line 674, in exec_module
  File "<frozen importlib._bootstrap_external>", line 781, in get_code
  File "<frozen importlib._bootstrap_external>", line 741, in source_to_code
  File "<frozen importlib._bootstrap>", line 205, in _call_with_frames_removed
  File "/home/peyrin/Desktop/Red-DiscordBot/cogs/remindme.py", line 71
    except (discord.errors.Forbidden, discord.errors.NotFound):
         ^
IndentationError: expected an indented block

During handling of the above exception, another exception occurred:

Traceback (most recent call last):
  File "red.py", line 570, in load_cogs
    owner_cog._load_cog(extension)
  File "/home/peyrin/Desktop/Red-DiscordBot/cogs/owner.py", line 949, in _load_cog
    raise CogLoadError(*e.args)
cogs.owner.CogLoadError: ('expected an indented block', ('/home/peyrin/Desktop/Red-DiscordBot/cogs/remindme.py', 71, 26, '                    except (discord.errors.Forbidden, discord.errors.NotFound):\n'))
[18/09/2017 00:42] ERROR red load_cogs 573: check_reminders() missing 1 required positional argument: 'ctx'
Traceback (most recent call last):
  File "red.py", line 570, in load_cogs
    owner_cog._load_cog(extension)
  File "/home/peyrin/Desktop/Red-DiscordBot/cogs/owner.py", line 947, in _load_cog
    self.bot.load_extension(mod_obj.__name__)
  File "lib/discord/ext/commands/bot.py", line 738, in load_extension
    lib.setup(self)
  File "/home/peyrin/Desktop/Red-DiscordBot/cogs/remindme.py", line 108, in setup
    loop.create_task(n.check_reminders())
TypeError: check_reminders() missing 1 required positional argument: 'ctx'
[18/09/2017 00:43] ERROR owner load 73: check_reminders() missing 1 required positional argument: 'ctx'
Traceback (most recent call last):
  File "/home/peyrin/Desktop/Red-DiscordBot/cogs/owner.py", line 64, in load
    self._load_cog(module)
  File "/home/peyrin/Desktop/Red-DiscordBot/cogs/owner.py", line 947, in _load_cog
    self.bot.load_extension(mod_obj.__name__)
  File "lib/discord/ext/commands/bot.py", line 738, in load_extension
    lib.setup(self)
  File "/home/peyrin/Desktop/Red-DiscordBot/cogs/remindme.py", line 107, in setup
    loop.create_task(n.check_reminders())
TypeError: check_reminders() missing 1 required positional argument: 'ctx'
[18/09/2017 01:48] ERROR owner load 73: name 'General' is not defined
Traceback (most recent call last):
  File "/home/peyrin/Desktop/Red-DiscordBot/cogs/owner.py", line 64, in load
    self._load_cog(module)
  File "/home/peyrin/Desktop/Red-DiscordBot/cogs/owner.py", line 947, in _load_cog
    self.bot.load_extension(mod_obj.__name__)
  File "lib/discord/ext/commands/bot.py", line 738, in load_extension
    lib.setup(self)
  File "/home/peyrin/Desktop/Red-DiscordBot/cogs/goodchat.py", line 73, in setup
    n = General(bot)
NameError: name 'General' is not defined
[18/09/2017 01:49] ERROR owner load 73: object() takes no parameters
Traceback (most recent call last):
  File "/home/peyrin/Desktop/Red-DiscordBot/cogs/owner.py", line 64, in load
    self._load_cog(module)
  File "/home/peyrin/Desktop/Red-DiscordBot/cogs/owner.py", line 947, in _load_cog
    self.bot.load_extension(mod_obj.__name__)
  File "lib/discord/ext/commands/bot.py", line 738, in load_extension
    lib.setup(self)
  File "/home/peyrin/Desktop/Red-DiscordBot/cogs/goodchat.py", line 73, in setup
    n = Goodchat(bot)
TypeError: object() takes no parameters
[18/09/2017 02:45] ERROR red on_command_error 369: Exception in command 'customcom add'
Traceback (most recent call last):
  File "lib/discord/ext/commands/core.py", line 50, in wrapped
    ret = yield from coro(*args, **kwargs)
  File "/home/peyrin/Desktop/Red-DiscordBot/cogs/customcom.py", line 48, in cc_add
    command_list = deque(cmdlist[command])
NameError: name 'deque' is not defined
[18/09/2017 02:46] ERROR red on_command_error 369: Exception in command 'customcom add'
Traceback (most recent call last):
  File "lib/discord/ext/commands/core.py", line 50, in wrapped
    ret = yield from coro(*args, **kwargs)
  File "/home/peyrin/Desktop/Red-DiscordBot/cogs/customcom.py", line 50, in cc_add
    self.past_names[before.id] = list(names)
NameError: name 'names' is not defined
[18/09/2017 02:47] ERROR red on_command_error 369: Exception in command 'customcom add'
Traceback (most recent call last):
  File "lib/discord/ext/commands/core.py", line 50, in wrapped
    ret = yield from coro(*args, **kwargs)
  File "/home/peyrin/Desktop/Red-DiscordBot/cogs/customcom.py", line 50, in cc_add
    cmdlist[command] = list(names)
NameError: name 'names' is not defined
[18/09/2017 03:26] ERROR red load_cogs 573: name 'customcom' is not defined
Traceback (most recent call last):
  File "red.py", line 570, in load_cogs
    owner_cog._load_cog(extension)
  File "/home/peyrin/Desktop/Red-DiscordBot/cogs/owner.py", line 945, in _load_cog
    mod_obj = importlib.import_module(cogname)
  File "/home/peyrin/anaconda3/lib/python3.6/importlib/__init__.py", line 126, in import_module
    return _bootstrap._gcd_import(name[level:], package, level)
  File "<frozen importlib._bootstrap>", line 978, in _gcd_import
  File "<frozen importlib._bootstrap>", line 961, in _find_and_load
  File "<frozen importlib._bootstrap>", line 950, in _find_and_load_unlocked
  File "<frozen importlib._bootstrap>", line 655, in _load_unlocked
  File "<frozen importlib._bootstrap_external>", line 678, in exec_module
  File "<frozen importlib._bootstrap>", line 205, in _call_with_frames_removed
  File "/home/peyrin/Desktop/Red-DiscordBot/cogs/customcom.py", line 10, in <module>
    class CustomCommands:
  File "/home/peyrin/Desktop/Red-DiscordBot/cogs/customcom.py", line 111, in CustomCommands
    @customcom.command(name="list", pass_context=True)
NameError: name 'customcom' is not defined
[18/09/2017 03:35] ERROR red on_command_error 369: Exception in command 'remember'
Traceback (most recent call last):
  File "lib/discord/ext/commands/core.py", line 50, in wrapped
    ret = yield from coro(*args, **kwargs)
  File "/home/peyrin/Desktop/Red-DiscordBot/cogs/customcom.py", line 140, in cc_list
    if server.id in self.c_commands and self.bot.user_allowed(message):
NameError: name 'message' is not defined
[18/09/2017 03:36] ERROR red on_command_error 369: Exception in command 'remember'
Traceback (most recent call last):
  File "lib/discord/ext/commands/core.py", line 50, in wrapped
    ret = yield from coro(*args, **kwargs)
  File "/home/peyrin/Desktop/Red-DiscordBot/cogs/customcom.py", line 143, in cc_list
    command_list = list(cmdlist[cmd])
NameError: name 'cmd' is not defined
[18/09/2017 03:37] ERROR red on_command_error 369: Exception in command 'remember'
Traceback (most recent call last):
  File "lib/discord/ext/commands/core.py", line 50, in wrapped
    ret = yield from coro(*args, **kwargs)
  File "/home/peyrin/Desktop/Red-DiscordBot/cogs/customcom.py", line 145, in cc_list
    result = command_list[number]
TypeError: list indices must be integers or slices, not str
[18/09/2017 03:37] ERROR red on_command_error 369: Exception in command 'remember'
Traceback (most recent call last):
  File "lib/discord/ext/commands/core.py", line 50, in wrapped
    ret = yield from coro(*args, **kwargs)
  File "/home/peyrin/Desktop/Red-DiscordBot/cogs/customcom.py", line 149, in cc_list
    result = self.format_cc(result, message)
NameError: name 'message' is not defined
[18/09/2017 03:38] ERROR red on_command_error 369: Exception in command 'remember'
Traceback (most recent call last):
  File "lib/discord/ext/commands/core.py", line 50, in wrapped
    ret = yield from coro(*args, **kwargs)
  File "/home/peyrin/Desktop/Red-DiscordBot/cogs/customcom.py", line 150, in cc_list
    await self.bot.send_message(message.channel, result)
NameError: name 'message' is not defined
[18/09/2017 14:58] ERROR red on_command_error 369: Exception in command 'slot'
Traceback (most recent call last):
  File "lib/discord/ext/commands/core.py", line 50, in wrapped
    ret = yield from coro(*args, **kwargs)
  File "/home/peyrin/Desktop/Red-DiscordBot/cogs/economy.py", line 596, in slot
    await self.slot_machine(author, bid)
  File "/home/peyrin/Desktop/Red-DiscordBot/cogs/economy.py", line 649, in slot_machine
    self.bank.set_credits(author, now)
AttributeError: 'Bank' object has no attribute 'set_credits'
[18/09/2017 14:58] ERROR red on_command_error 369: Exception in command 'slot'
Traceback (most recent call last):
  File "lib/discord/ext/commands/core.py", line 50, in wrapped
    ret = yield from coro(*args, **kwargs)
  File "/home/peyrin/Desktop/Red-DiscordBot/cogs/economy.py", line 596, in slot
    await self.slot_machine(author, bid)
  File "/home/peyrin/Desktop/Red-DiscordBot/cogs/economy.py", line 649, in slot_machine
    self.bank.set_credits(author, now)
AttributeError: 'Bank' object has no attribute 'set_credits'
[18/09/2017 18:26] ERROR red load_cogs 573: Neither ffmpeg nor avconv are installed.
Consult the guide for your operating system and do ALL the steps in order.
https://twentysix26.github.io/Red-Docs/
Traceback (most recent call last):
  File "red.py", line 570, in load_cogs
    owner_cog._load_cog(extension)
  File "/home/peyrin/Desktop/Red-DiscordBot/cogs/owner.py", line 947, in _load_cog
    self.bot.load_extension(mod_obj.__name__)
  File "lib/discord/ext/commands/bot.py", line 738, in load_extension
    lib.setup(self)
  File "/home/peyrin/Desktop/Red-DiscordBot/cogs/audio.py", line 2390, in setup
    "".format(msg))
RuntimeError: Neither ffmpeg nor avconv are installed.
Consult the guide for your operating system and do ALL the steps in order.
https://twentysix26.github.io/Red-Docs/

[18/09/2017 19:04] ERROR red <module> 634: Fatal exception, attempting graceful logout
Traceback (most recent call last):
  File "lib/discord/gateway.py", line 430, in poll_event
    msg = yield from self.recv()
  File "lib/websockets/protocol.py", line 319, in recv
    raise ConnectionClosed(self.close_code, self.close_reason)
websockets.exceptions.ConnectionClosed: WebSocket connection is closed: no code, no reason.

The above exception was the direct cause of the following exception:

Traceback (most recent call last):
  File "lib/discord/client.py", line 448, in connect
    yield from self.ws.poll_event()
  File "lib/discord/gateway.py", line 435, in poll_event
    raise ResumeWebSocket() from e
discord.gateway.ResumeWebSocket

During handling of the above exception, another exception occurred:

Traceback (most recent call last):
  File "lib/aiohttp/connector.py", line 601, in _create_direct_connection
    local_addr=self._local_addr)
  File "/home/peyrin/anaconda3/lib/python3.6/asyncio/base_events.py", line 776, in create_connection
    raise exceptions[0]
  File "/home/peyrin/anaconda3/lib/python3.6/asyncio/base_events.py", line 763, in create_connection
    yield from self.sock_connect(sock, address)
  File "/home/peyrin/anaconda3/lib/python3.6/asyncio/selector_events.py", line 451, in sock_connect
    return (yield from fut)
  File "/home/peyrin/anaconda3/lib/python3.6/asyncio/selector_events.py", line 456, in _sock_connect
    sock.connect(address)
OSError: [Errno 101] Network is unreachable

The above exception was the direct cause of the following exception:

Traceback (most recent call last):
  File "lib/aiohttp/connector.py", line 304, in connect
    yield from self._create_connection(req)
  File "lib/aiohttp/connector.py", line 578, in _create_connection
    transport, proto = yield from self._create_direct_connection(req)
  File "lib/aiohttp/connector.py", line 624, in _create_direct_connection
    (req.host, req.port, exc.strerror)) from exc
aiohttp.errors.ClientOSError: [Errno 101] Can not connect to discordapp.com:443 [Network is unreachable]

The above exception was the direct cause of the following exception:

Traceback (most recent call last):
  File "red.py", line 614, in <module>
    loop.run_until_complete(main(bot))
  File "/home/peyrin/anaconda3/lib/python3.6/asyncio/base_events.py", line 466, in run_until_complete
    return future.result()
  File "red.py", line 603, in main
    yield from bot.connect()
  File "lib/discord/client.py", line 452, in connect
    self.ws = yield from DiscordWebSocket.from_client(self, resume=resume)
  File "lib/discord/gateway.py", line 203, in from_client
    gateway = yield from client.http.get_gateway()
  File "lib/discord/http.py", line 633, in get_gateway
    data = yield from self.request(Route('GET', '/gateway'))
  File "lib/discord/http.py", line 137, in request
    r = yield from self.session.request(method, url, **kwargs)
  File "lib/aiohttp/client.py", line 555, in __iter__
    resp = yield from self._coro
  File "lib/aiohttp/client.py", line 198, in _request
    conn = yield from self._connector.connect(req)
  File "lib/aiohttp/connector.py", line 314, in connect
    .format(key, exc.strerror)) from exc
aiohttp.errors.ClientOSError: [Errno 101] Cannot connect to host discordapp.com:443 ssl:True [Can not connect to discordapp.com:443 [Network is unreachable]]
[18/09/2017 19:25] ERROR red on_command_error 369: Exception in command 'rps'
Traceback (most recent call last):
  File "lib/discord/ext/commands/core.py", line 50, in wrapped
    ret = yield from coro(*args, **kwargs)
  File "/home/peyrin/Desktop/Red-DiscordBot/cogs/economy.py", line 574, in rps
    await self.bot.say(rpsmsg)
  File "lib/discord/ext/commands/bot.py", line 309, in _augmented_msg
    msg = yield from coro
  File "red.py", line 92, in send_message
    return await super().send_message(*args, **kwargs)
  File "lib/discord/client.py", line 1152, in send_message
    data = yield from self.http.send_message(channel_id, content, guild_id=guild_id, tts=tts, embed=embed)
  File "lib/discord/http.py", line 200, in request
    raise HTTPException(r, data)
discord.errors.HTTPException: Origin Error (status code: 520): <!DOCTYPE html>
<!--[if lt IE 7]> <html class="no-js ie6 oldie" lang="en-US"> <![endif]-->
<!--[if IE 7]>    <html class="no-js ie7 oldie" lang="en-US"> <![endif]-->
<!--[if IE 8]>    <html class="no-js ie8 oldie" lang="en-US"> <![endif]-->
<!--[if gt IE 8]><!--> <html class="no-js" lang="en-US"> <!--<![endif]-->
<head>


<meta http-equiv="set-cookie" content="cf_use_ob=0; expires=Tue, 19-Sep-17 02:25:31 GMT; path=/">


<title>discordapp.com | 520: Web server is returning an unknown error</title>
<meta charset="UTF-8" />
<meta http-equiv="Content-Type" content="text/html; charset=UTF-8" />
<meta http-equiv="X-UA-Compatible" content="IE=Edge,chrome=1" />
<meta name="robots" content="noindex, nofollow" />
<meta name="viewport" content="width=device-width,initial-scale=1,maximum-scale=1" />
<link rel="stylesheet" id="cf_styles-css" href="/cdn-cgi/styles/cf.errors.css" type="text/css" media="screen,projection" />
<!--[if lt IE 9]><link rel="stylesheet" id='cf_styles-ie-css' href="/cdn-cgi/styles/cf.errors.ie.css" type="text/css" media="screen,projection" /><![endif]-->
<style type="text/css">body{margin:0;padding:0}</style>
<!--[if lte IE 9]><script type="text/javascript" src="/cdn-cgi/scripts/jquery.min.js"></script><![endif]-->
<!--[if gte IE 10]><!--><script type="text/javascript" src="/cdn-cgi/scripts/zepto.min.js"></script><!--<![endif]-->
<script type="text/javascript" src="/cdn-cgi/scripts/cf.common.js"></script>

</head>
<body>
<div id="cf-wrapper">

    

    <div id="cf-error-details" class="cf-error-details-wrapper">
        <div class="cf-wrapper cf-error-overview">
            <h1>
              <span class="cf-error-type" data-translate="error">Error</span>
              <span class="cf-error-code">520</span>
              <small class="heading-ray-id">Ray ID: 3a091792ed286c58 &bull; 2017-09-19 02:25:01 UTC</small>
            </h1>
            <h2 class="cf-subheadline" data-translate="error_desc">Web server is returning an unknown error</h2>
        </div><!-- /.error-overview -->

        <div class="cf-section cf-highlight cf-status-display">
            <div class="cf-wrapper">
                <div class="cf-columns cols-3">
                  
<div id="cf-browser-status" class="cf-column cf-status-item cf-browser-status ">
  <div class="cf-icon-error-container">
    <i class="cf-icon cf-icon-browser"></i>
    <i class="cf-icon-status cf-icon-ok"></i>
  </div>
  <span class="cf-status-desc" data-translate="browser_desc">You</span>
  <h3 class="cf-status-name" data-translate="browser_label">Browser</h3>
  <span class="cf-status-label" data-translate="browser_status_label">Working</span>
</div>

<div id="cf-cloudflare-status" class="cf-column cf-status-item cf-cloudflare-status ">
  <div class="cf-icon-error-container">
    <i class="cf-icon cf-icon-cloud"></i>
    <i class="cf-icon-status cf-icon-ok"></i>
  </div>
  <span class="cf-status-desc" data-translate="cloud_desc">San Jose</span>
  <h3 class="cf-status-name" data-translate="cloud_label">Cloudflare</h3>
  <span class="cf-status-label" data-translate="cloud_status_label">Working</span>
</div>

<div id="cf-host-status" class="cf-column cf-status-item cf-host-status cf-error-source">
  <div class="cf-icon-error-container">
    <i class="cf-icon cf-icon-server"></i>
    <i class="cf-icon-status cf-icon-error"></i>
  </div>
  <span class="cf-status-desc" data-translate="server_desc">discordapp.com</span>
  <h3 class="cf-status-name" data-translate="server_label">Host</h3>
  <span class="cf-status-label" data-translate="server_status_label">Error</span>
</div>

                </div>
            </div>
        </div><!-- /.status-display -->

        <div class="cf-section cf-wrapper">
            <div class="cf-columns two">
                <div class="cf-column">
                    <h2 data-translate="what_happened">What happened?</h2>
                    <p data-translate="unknown_error_desc">There is an unknown connection issue between Cloudflare and the origin web server. As a result, the web page can not be displayed.</p>
                </div>

                <div class="cf-column">
                    <h2 data-translate="what_can_i_do">What can I do?</h2>
                          <h5 data-translate="if_website_visitor">If you are a visitor of this website:</h5>
      <p data-translate="try_again_in_a_few">Please try again in a few minutes.</p>

      <h5 data-translate="if_website_owner">If you are the owner of this website:</h5>
      <p><span data-translate="520_owner_desc">There is an issue between Cloudflare's cache and your origin web server. Cloudflare monitors for these errors and automatically investigates the cause. To help support the investigation, you can pull the corresponding error log from your web server and submit it our support team.  Please include the Ray ID (which is at the bottom of this error page).</span> <a href="https://support.cloudflare.com/hc/en-us/articles/200171936-Error-520" data-translate="addtl_troubleshooting">Additional troubleshooting resources</a>.</p>
                </div>
            </div>
        </div><!-- /.section -->

        <div class="cf-error-footer cf-wrapper">
  <p>
    <span class="cf-footer-item">Cloudflare Ray ID: <strong>3a091792ed286c58</strong></span>
    <span class="cf-footer-separator">&bull;</span>
    <span class="cf-footer-item"><span data-translate="your_ip">Your IP</span>: 192.31.105.229</span>
    <span class="cf-footer-separator">&bull;</span>
    <span class="cf-footer-item"><span data-translate="performance_security_by">Performance &amp; security by</span> <a data-orig-proto="https" data-orig-ref="www.cloudflare.com/5xx-error-landing?utm_source=error_footer" id="brand_link" target="_blank">Cloudflare</a></span>
    
  </p>
</div><!-- /.error-footer -->


    </div><!-- /#cf-error-details -->
</div><!-- /#cf-wrapper -->

[18/09/2017 19:29] INFO economy transfer 353: Andre(350058699815124992) transferred 2000 credits to Igor(312773714280185856)
[18/09/2017 21:16] ERROR red <module> 634: Fatal exception, attempting graceful logout
Traceback (most recent call last):
  File "lib/discord/gateway.py", line 430, in poll_event
    msg = yield from self.recv()
  File "lib/websockets/protocol.py", line 319, in recv
    raise ConnectionClosed(self.close_code, self.close_reason)
websockets.exceptions.ConnectionClosed: WebSocket connection is closed: no code, no reason.

The above exception was the direct cause of the following exception:

Traceback (most recent call last):
  File "lib/discord/client.py", line 448, in connect
    yield from self.ws.poll_event()
  File "lib/discord/gateway.py", line 435, in poll_event
    raise ResumeWebSocket() from e
discord.gateway.ResumeWebSocket

During handling of the above exception, another exception occurred:

Traceback (most recent call last):
  File "lib/aiohttp/connector.py", line 601, in _create_direct_connection
    local_addr=self._local_addr)
  File "/home/peyrin/anaconda3/lib/python3.6/asyncio/base_events.py", line 776, in create_connection
    raise exceptions[0]
  File "/home/peyrin/anaconda3/lib/python3.6/asyncio/base_events.py", line 763, in create_connection
    yield from self.sock_connect(sock, address)
  File "/home/peyrin/anaconda3/lib/python3.6/asyncio/selector_events.py", line 451, in sock_connect
    return (yield from fut)
  File "/home/peyrin/anaconda3/lib/python3.6/asyncio/selector_events.py", line 456, in _sock_connect
    sock.connect(address)
OSError: [Errno 101] Network is unreachable

The above exception was the direct cause of the following exception:

Traceback (most recent call last):
  File "lib/aiohttp/connector.py", line 304, in connect
    yield from self._create_connection(req)
  File "lib/aiohttp/connector.py", line 578, in _create_connection
    transport, proto = yield from self._create_direct_connection(req)
  File "lib/aiohttp/connector.py", line 624, in _create_direct_connection
    (req.host, req.port, exc.strerror)) from exc
aiohttp.errors.ClientOSError: [Errno 101] Can not connect to discordapp.com:443 [Network is unreachable]

The above exception was the direct cause of the following exception:

Traceback (most recent call last):
  File "red.py", line 614, in <module>
    loop.run_until_complete(main(bot))
  File "/home/peyrin/anaconda3/lib/python3.6/asyncio/base_events.py", line 466, in run_until_complete
    return future.result()
  File "red.py", line 603, in main
    yield from bot.connect()
  File "lib/discord/client.py", line 452, in connect
    self.ws = yield from DiscordWebSocket.from_client(self, resume=resume)
  File "lib/discord/gateway.py", line 203, in from_client
    gateway = yield from client.http.get_gateway()
  File "lib/discord/http.py", line 633, in get_gateway
    data = yield from self.request(Route('GET', '/gateway'))
  File "lib/discord/http.py", line 137, in request
    r = yield from self.session.request(method, url, **kwargs)
  File "lib/aiohttp/client.py", line 555, in __iter__
    resp = yield from self._coro
  File "lib/aiohttp/client.py", line 198, in _request
    conn = yield from self._connector.connect(req)
  File "lib/aiohttp/connector.py", line 314, in connect
    .format(key, exc.strerror)) from exc
aiohttp.errors.ClientOSError: [Errno 101] Cannot connect to host discordapp.com:443 ssl:True [Can not connect to discordapp.com:443 [Network is unreachable]]
