[17/09/2017 22:10] ERROR red load_cogs 573: You need to run `pip3 install youtube_dl`
Traceback (most recent call last):
  File "red.py", line 570, in load_cogs
    owner_cog._load_cog(extension)
  File "/home/peyrin/Desktop/Red-DiscordBot/cogs/owner.py", line 947, in _load_cog
    self.bot.load_extension(mod_obj.__name__)
  File "/home/peyrin/anaconda3/lib/python3.6/site-packages/discord/ext/commands/bot.py", line 738, in load_extension
    lib.setup(self)
  File "/home/peyrin/Desktop/Red-DiscordBot/cogs/audio.py", line 2369, in setup
    raise RuntimeError("You need to run `pip3 install youtube_dl`")
RuntimeError: You need to run `pip3 install youtube_dl`
[17/09/2017 22:10] ERROR red load_cogs 573: Command rps is already registered.
Traceback (most recent call last):
  File "red.py", line 570, in load_cogs
    owner_cog._load_cog(extension)
  File "/home/peyrin/Desktop/Red-DiscordBot/cogs/owner.py", line 947, in _load_cog
    self.bot.load_extension(mod_obj.__name__)
  File "/home/peyrin/anaconda3/lib/python3.6/site-packages/discord/ext/commands/bot.py", line 738, in load_extension
    lib.setup(self)
  File "/home/peyrin/Desktop/Red-DiscordBot/cogs/general.py", line 434, in setup
    bot.add_cog(n)
  File "/home/peyrin/anaconda3/lib/python3.6/site-packages/discord/ext/commands/bot.py", line 655, in add_cog
    self.add_command(member)
  File "/home/peyrin/anaconda3/lib/python3.6/site-packages/discord/ext/commands/core.py", line 487, in add_command
    raise discord.ClientException('Command {0.name} is already registered.'.format(command))
discord.errors.ClientException: Command rps is already registered.
[17/09/2017 22:10] ERROR red load_cogs 573: You need the imgurpython module to use this.
pip3 install imgurpython
Traceback (most recent call last):
  File "red.py", line 570, in load_cogs
    owner_cog._load_cog(extension)
  File "/home/peyrin/Desktop/Red-DiscordBot/cogs/owner.py", line 947, in _load_cog
    self.bot.load_extension(mod_obj.__name__)
  File "/home/peyrin/anaconda3/lib/python3.6/site-packages/discord/ext/commands/bot.py", line 738, in load_extension
    lib.setup(self)
  File "/home/peyrin/Desktop/Red-DiscordBot/cogs/image.py", line 165, in setup
    raise RuntimeError("You need the imgurpython module to use this.\n"
RuntimeError: You need the imgurpython module to use this.
pip3 install imgurpython
[17/09/2017 22:25] ERROR owner load 73: Command rps is already registered.
Traceback (most recent call last):
  File "/home/peyrin/Desktop/Red-DiscordBot/cogs/owner.py", line 64, in load
    self._load_cog(module)
  File "/home/peyrin/Desktop/Red-DiscordBot/cogs/owner.py", line 947, in _load_cog
    self.bot.load_extension(mod_obj.__name__)
  File "lib/discord/ext/commands/bot.py", line 738, in load_extension
    lib.setup(self)
  File "/home/peyrin/Desktop/Red-DiscordBot/cogs/general.py", line 434, in setup
    bot.add_cog(n)
  File "lib/discord/ext/commands/bot.py", line 655, in add_cog
    self.add_command(member)
  File "lib/discord/ext/commands/core.py", line 487, in add_command
    raise discord.ClientException('Command {0.name} is already registered.'.format(command))
discord.errors.ClientException: Command rps is already registered.
[17/09/2017 22:43] ERROR red load_cogs 573: ('invalid syntax', ('/home/peyrin/Desktop/Red-DiscordBot/cogs/general.py', 180, 34, '    async def whodunit(self, ctx)\n'))
Traceback (most recent call last):
  File "/home/peyrin/Desktop/Red-DiscordBot/cogs/owner.py", line 945, in _load_cog
    mod_obj = importlib.import_module(cogname)
  File "/home/peyrin/anaconda3/lib/python3.6/importlib/__init__.py", line 126, in import_module
    return _bootstrap._gcd_import(name[level:], package, level)
  File "<frozen importlib._bootstrap>", line 978, in _gcd_import
  File "<frozen importlib._bootstrap>", line 961, in _find_and_load
  File "<frozen importlib._bootstrap>", line 950, in _find_and_load_unlocked
  File "<frozen importlib._bootstrap>", line 655, in _load_unlocked
  File "<frozen importlib._bootstrap_external>", line 674, in exec_module
  File "<frozen importlib._bootstrap_external>", line 781, in get_code
  File "<frozen importlib._bootstrap_external>", line 741, in source_to_code
  File "<frozen importlib._bootstrap>", line 205, in _call_with_frames_removed
  File "/home/peyrin/Desktop/Red-DiscordBot/cogs/general.py", line 180
    async def whodunit(self, ctx)
                                ^
SyntaxError: invalid syntax

During handling of the above exception, another exception occurred:

Traceback (most recent call last):
  File "red.py", line 570, in load_cogs
    owner_cog._load_cog(extension)
  File "/home/peyrin/Desktop/Red-DiscordBot/cogs/owner.py", line 949, in _load_cog
    raise CogLoadError(*e.args)
cogs.owner.CogLoadError: ('invalid syntax', ('/home/peyrin/Desktop/Red-DiscordBot/cogs/general.py', 180, 34, '    async def whodunit(self, ctx)\n'))
[17/09/2017 22:43] ERROR owner load 73: name 'pass_context_True' is not defined
Traceback (most recent call last):
  File "/home/peyrin/Desktop/Red-DiscordBot/cogs/owner.py", line 64, in load
    self._load_cog(module)
  File "/home/peyrin/Desktop/Red-DiscordBot/cogs/owner.py", line 945, in _load_cog
    mod_obj = importlib.import_module(cogname)
  File "/home/peyrin/anaconda3/lib/python3.6/importlib/__init__.py", line 126, in import_module
    return _bootstrap._gcd_import(name[level:], package, level)
  File "<frozen importlib._bootstrap>", line 978, in _gcd_import
  File "<frozen importlib._bootstrap>", line 961, in _find_and_load
  File "<frozen importlib._bootstrap>", line 950, in _find_and_load_unlocked
  File "<frozen importlib._bootstrap>", line 655, in _load_unlocked
  File "<frozen importlib._bootstrap_external>", line 678, in exec_module
  File "<frozen importlib._bootstrap>", line 205, in _call_with_frames_removed
  File "/home/peyrin/Desktop/Red-DiscordBot/cogs/general.py", line 36, in <module>
    class General:
  File "/home/peyrin/Desktop/Red-DiscordBot/cogs/general.py", line 179, in General
    @commands.command(pass_context_True, no_pm=True)
NameError: name 'pass_context_True' is not defined
[17/09/2017 22:44] ERROR red on_command_error 369: Exception in command 'whodunit'
Traceback (most recent call last):
  File "lib/discord/ext/commands/core.py", line 50, in wrapped
    ret = yield from coro(*args, **kwargs)
  File "/home/peyrin/Desktop/Red-DiscordBot/cogs/general.py", line 184, in whodunit
    await self.bot.say("It was " + choice(member_list) + "!!!")
  File "/home/peyrin/anaconda3/lib/python3.6/random.py", line 258, in choice
    return seq[i]
TypeError: 'dict_values' object does not support indexing
[17/09/2017 22:45] ERROR red on_command_error 369: Exception in command 'whodunit'
Traceback (most recent call last):
  File "lib/discord/ext/commands/core.py", line 50, in wrapped
    ret = yield from coro(*args, **kwargs)
  File "/home/peyrin/Desktop/Red-DiscordBot/cogs/general.py", line 184, in whodunit
    await self.bot.say("It was " + choice(member_list) + "!!!")
TypeError: must be str, not Member
[17/09/2017 22:46] ERROR red on_command_error 369: Exception in command 'whodunit'
Traceback (most recent call last):
  File "lib/discord/ext/commands/core.py", line 50, in wrapped
    ret = yield from coro(*args, **kwargs)
  File "/home/peyrin/Desktop/Red-DiscordBot/cogs/general.py", line 184, in whodunit
    await self.bot.say("It was " + choice(member_list).nick + "!!!")
TypeError: must be str, not NoneType
[17/09/2017 22:50] ERROR red load_cogs 573: name 'ctx' is not defined
Traceback (most recent call last):
  File "red.py", line 570, in load_cogs
    owner_cog._load_cog(extension)
  File "/home/peyrin/Desktop/Red-DiscordBot/cogs/owner.py", line 947, in _load_cog
    self.bot.load_extension(mod_obj.__name__)
  File "lib/discord/ext/commands/bot.py", line 738, in load_extension
    lib.setup(self)
  File "/home/peyrin/Desktop/Red-DiscordBot/cogs/general.py", line 439, in setup
    n = General(bot)
  File "/home/peyrin/Desktop/Red-DiscordBot/cogs/general.py", line 47, in __init__
    server = ctx.message.server
NameError: name 'ctx' is not defined
[17/09/2017 23:35] ERROR red on_command_error 369: Exception in command 'colors'
Traceback (most recent call last):
  File "lib/discord/ext/commands/core.py", line 50, in wrapped
    ret = yield from coro(*args, **kwargs)
  File "/home/peyrin/Desktop/Red-DiscordBot/cogs/mod.py", line 174, in colors
    role_list = list(server.roles.name)
AttributeError: 'list' object has no attribute 'name'
[17/09/2017 23:36] ERROR red load_cogs 573: ('invalid syntax', ('/home/peyrin/Desktop/Red-DiscordBot/cogs/mod.py', 175, 30, '        role_list = e.name for e in role_list\n'))
Traceback (most recent call last):
  File "/home/peyrin/Desktop/Red-DiscordBot/cogs/owner.py", line 945, in _load_cog
    mod_obj = importlib.import_module(cogname)
  File "/home/peyrin/anaconda3/lib/python3.6/importlib/__init__.py", line 126, in import_module
    return _bootstrap._gcd_import(name[level:], package, level)
  File "<frozen importlib._bootstrap>", line 978, in _gcd_import
  File "<frozen importlib._bootstrap>", line 961, in _find_and_load
  File "<frozen importlib._bootstrap>", line 950, in _find_and_load_unlocked
  File "<frozen importlib._bootstrap>", line 655, in _load_unlocked
  File "<frozen importlib._bootstrap_external>", line 674, in exec_module
  File "<frozen importlib._bootstrap_external>", line 781, in get_code
  File "<frozen importlib._bootstrap_external>", line 741, in source_to_code
  File "<frozen importlib._bootstrap>", line 205, in _call_with_frames_removed
  File "/home/peyrin/Desktop/Red-DiscordBot/cogs/mod.py", line 175
    role_list = e.name for e in role_list
                         ^
SyntaxError: invalid syntax

During handling of the above exception, another exception occurred:

Traceback (most recent call last):
  File "red.py", line 570, in load_cogs
    owner_cog._load_cog(extension)
  File "/home/peyrin/Desktop/Red-DiscordBot/cogs/owner.py", line 949, in _load_cog
    raise CogLoadError(*e.args)
cogs.owner.CogLoadError: ('invalid syntax', ('/home/peyrin/Desktop/Red-DiscordBot/cogs/mod.py', 175, 30, '        role_list = e.name for e in role_list\n'))
[17/09/2017 23:37] ERROR red on_command_error 369: Exception in command 'colors'
Traceback (most recent call last):
  File "lib/discord/ext/commands/core.py", line 50, in wrapped
    ret = yield from coro(*args, **kwargs)
  File "/home/peyrin/Desktop/Red-DiscordBot/cogs/mod.py", line 177, in colors
    role_list.remove('overlord').remove('Edmund').remove('Bots').remove('can mod people')
ValueError: list.remove(x): x not in list
[17/09/2017 23:38] ERROR red load_cogs 573: ('invalid syntax', ('/home/peyrin/Desktop/Red-DiscordBot/cogs/mod.py', 180, 15, "        message = ', '.join(e for e in role_list)\n"))
Traceback (most recent call last):
  File "/home/peyrin/Desktop/Red-DiscordBot/cogs/owner.py", line 945, in _load_cog
    mod_obj = importlib.import_module(cogname)
  File "/home/peyrin/anaconda3/lib/python3.6/importlib/__init__.py", line 126, in import_module
    return _bootstrap._gcd_import(name[level:], package, level)
  File "<frozen importlib._bootstrap>", line 978, in _gcd_import
  File "<frozen importlib._bootstrap>", line 961, in _find_and_load
  File "<frozen importlib._bootstrap>", line 950, in _find_and_load_unlocked
  File "<frozen importlib._bootstrap>", line 655, in _load_unlocked
  File "<frozen importlib._bootstrap_external>", line 674, in exec_module
  File "<frozen importlib._bootstrap_external>", line 781, in get_code
  File "<frozen importlib._bootstrap_external>", line 741, in source_to_code
  File "<frozen importlib._bootstrap>", line 205, in _call_with_frames_removed
  File "/home/peyrin/Desktop/Red-DiscordBot/cogs/mod.py", line 180
    message = ', '.join(e for e in role_list)
          ^
SyntaxError: invalid syntax

During handling of the above exception, another exception occurred:

Traceback (most recent call last):
  File "red.py", line 570, in load_cogs
    owner_cog._load_cog(extension)
  File "/home/peyrin/Desktop/Red-DiscordBot/cogs/owner.py", line 949, in _load_cog
    raise CogLoadError(*e.args)
cogs.owner.CogLoadError: ('invalid syntax', ('/home/peyrin/Desktop/Red-DiscordBot/cogs/mod.py', 180, 15, "        message = ', '.join(e for e in role_list)\n"))
[17/09/2017 23:42] ERROR owner load 68: ('invalid syntax', ('/home/peyrin/Desktop/Red-DiscordBot/cogs/mod.py', 180, 15, "        message = ''\n"))
Traceback (most recent call last):
  File "/home/peyrin/Desktop/Red-DiscordBot/cogs/owner.py", line 945, in _load_cog
    mod_obj = importlib.import_module(cogname)
  File "/home/peyrin/anaconda3/lib/python3.6/importlib/__init__.py", line 126, in import_module
    return _bootstrap._gcd_import(name[level:], package, level)
  File "<frozen importlib._bootstrap>", line 978, in _gcd_import
  File "<frozen importlib._bootstrap>", line 961, in _find_and_load
  File "<frozen importlib._bootstrap>", line 950, in _find_and_load_unlocked
  File "<frozen importlib._bootstrap>", line 655, in _load_unlocked
  File "<frozen importlib._bootstrap_external>", line 674, in exec_module
  File "<frozen importlib._bootstrap_external>", line 781, in get_code
  File "<frozen importlib._bootstrap_external>", line 741, in source_to_code
  File "<frozen importlib._bootstrap>", line 205, in _call_with_frames_removed
  File "/home/peyrin/Desktop/Red-DiscordBot/cogs/mod.py", line 180
    message = ''
          ^
SyntaxError: invalid syntax

During handling of the above exception, another exception occurred:

Traceback (most recent call last):
  File "/home/peyrin/Desktop/Red-DiscordBot/cogs/owner.py", line 64, in load
    self._load_cog(module)
  File "/home/peyrin/Desktop/Red-DiscordBot/cogs/owner.py", line 949, in _load_cog
    raise CogLoadError(*e.args)
cogs.owner.CogLoadError: ('invalid syntax', ('/home/peyrin/Desktop/Red-DiscordBot/cogs/mod.py', 180, 15, "        message = ''\n"))
[17/09/2017 23:43] ERROR red on_command_error 369: Exception in command 'colors'
Traceback (most recent call last):
  File "lib/discord/ext/commands/core.py", line 50, in wrapped
    ret = yield from coro(*args, **kwargs)
  File "/home/peyrin/Desktop/Red-DiscordBot/cogs/mod.py", line 181, in colors
    message.join(e)
TypeError: can only join an iterable
[17/09/2017 23:44] ERROR red on_command_error 369: Exception in command 'colors'
Traceback (most recent call last):
  File "lib/discord/ext/commands/core.py", line 50, in wrapped
    ret = yield from coro(*args, **kwargs)
  File "/home/peyrin/Desktop/Red-DiscordBot/cogs/mod.py", line 180, in colors
    message.join(',', role_list)
TypeError: join() takes exactly one argument (2 given)
[17/09/2017 23:46] ERROR red on_command_error 369: Exception in command 'colors'
Traceback (most recent call last):
  File "lib/discord/ext/commands/core.py", line 50, in wrapped
    ret = yield from coro(*args, **kwargs)
  File "/home/peyrin/Desktop/Red-DiscordBot/cogs/mod.py", line 179, in colors
    await self.bot.say(','.join(role_list))
TypeError: sequence item 0: expected str instance, Role found
[17/09/2017 23:46] ERROR red on_command_error 369: Exception in command 'colors'
Traceback (most recent call last):
  File "lib/discord/ext/commands/core.py", line 50, in wrapped
    ret = yield from coro(*args, **kwargs)
  File "/home/peyrin/Desktop/Red-DiscordBot/cogs/mod.py", line 177, in colors
    await self.bot.say(','.join(role_list))
  File "lib/discord/ext/commands/bot.py", line 309, in _augmented_msg
    msg = yield from coro
  File "red.py", line 92, in send_message
    return await super().send_message(*args, **kwargs)
  File "lib/discord/client.py", line 1152, in send_message
    data = yield from self.http.send_message(channel_id, content, guild_id=guild_id, tts=tts, embed=embed)
  File "lib/discord/http.py", line 200, in request
    raise HTTPException(r, data)
discord.errors.HTTPException: BAD REQUEST (status code: 400)
[17/09/2017 23:47] ERROR red on_command_error 369: Exception in command 'colors'
Traceback (most recent call last):
  File "lib/discord/ext/commands/core.py", line 50, in wrapped
    ret = yield from coro(*args, **kwargs)
  File "/home/peyrin/Desktop/Red-DiscordBot/cogs/mod.py", line 177, in colors
    await self.bot.say(','.join(role_list))
  File "lib/discord/ext/commands/bot.py", line 309, in _augmented_msg
    msg = yield from coro
  File "red.py", line 92, in send_message
    return await super().send_message(*args, **kwargs)
  File "lib/discord/client.py", line 1152, in send_message
    data = yield from self.http.send_message(channel_id, content, guild_id=guild_id, tts=tts, embed=embed)
  File "lib/discord/http.py", line 200, in request
    raise HTTPException(r, data)
discord.errors.HTTPException: BAD REQUEST (status code: 400)
[17/09/2017 23:48] ERROR red on_command_error 369: Exception in command 'colors'
Traceback (most recent call last):
  File "lib/discord/ext/commands/core.py", line 50, in wrapped
    ret = yield from coro(*args, **kwargs)
  File "/home/peyrin/Desktop/Red-DiscordBot/cogs/mod.py", line 179, in colors
    await self.bot.say(','.join(role_list))
TypeError: sequence item 0: expected str instance, Role found
[17/09/2017 23:52] ERROR red on_command_error 369: Exception in command 'colors'
Traceback (most recent call last):
  File "lib/discord/ext/commands/core.py", line 50, in wrapped
    ret = yield from coro(*args, **kwargs)
  File "/home/peyrin/Desktop/Red-DiscordBot/cogs/mod.py", line 178, in colors
    role_strings.remove('overlord').remove('Edmund').remove('Bots').remove('can mod people')
AttributeError: 'NoneType' object has no attribute 'remove'
[17/09/2017 23:57] ERROR red on_command_error 369: Exception in command 'colors'
Traceback (most recent call last):
  File "lib/discord/ext/commands/core.py", line 50, in wrapped
    ret = yield from coro(*args, **kwargs)
  File "/home/peyrin/Desktop/Red-DiscordBot/cogs/mod.py", line 176, in colors
    reverse(role_list)
NameError: name 'reverse' is not defined
[18/09/2017 00:37] ERROR red load_cogs 573: ('expected an indented block', ('/home/peyrin/Desktop/Red-DiscordBot/cogs/remindme.py', 71, 26, '                    except (discord.errors.Forbidden, discord.errors.NotFound):\n'))
Traceback (most recent call last):
  File "/home/peyrin/Desktop/Red-DiscordBot/cogs/owner.py", line 945, in _load_cog
    mod_obj = importlib.import_module(cogname)
  File "/home/peyrin/anaconda3/lib/python3.6/importlib/__init__.py", line 126, in import_module
    return _bootstrap._gcd_import(name[level:], package, level)
  File "<frozen importlib._bootstrap>", line 978, in _gcd_import
  File "<frozen importlib._bootstrap>", line 961, in _find_and_load
  File "<frozen importlib._bootstrap>", line 950, in _find_and_load_unlocked
  File "<frozen importlib._bootstrap>", line 655, in _load_unlocked
  File "<frozen importlib._bootstrap_external>", line 674, in exec_module
  File "<frozen importlib._bootstrap_external>", line 781, in get_code
  File "<frozen importlib._bootstrap_external>", line 741, in source_to_code
  File "<frozen importlib._bootstrap>", line 205, in _call_with_frames_removed
  File "/home/peyrin/Desktop/Red-DiscordBot/cogs/remindme.py", line 71
    except (discord.errors.Forbidden, discord.errors.NotFound):
         ^
IndentationError: expected an indented block

During handling of the above exception, another exception occurred:

Traceback (most recent call last):
  File "red.py", line 570, in load_cogs
    owner_cog._load_cog(extension)
  File "/home/peyrin/Desktop/Red-DiscordBot/cogs/owner.py", line 949, in _load_cog
    raise CogLoadError(*e.args)
cogs.owner.CogLoadError: ('expected an indented block', ('/home/peyrin/Desktop/Red-DiscordBot/cogs/remindme.py', 71, 26, '                    except (discord.errors.Forbidden, discord.errors.NotFound):\n'))
[18/09/2017 00:42] ERROR red load_cogs 573: check_reminders() missing 1 required positional argument: 'ctx'
Traceback (most recent call last):
  File "red.py", line 570, in load_cogs
    owner_cog._load_cog(extension)
  File "/home/peyrin/Desktop/Red-DiscordBot/cogs/owner.py", line 947, in _load_cog
    self.bot.load_extension(mod_obj.__name__)
  File "lib/discord/ext/commands/bot.py", line 738, in load_extension
    lib.setup(self)
  File "/home/peyrin/Desktop/Red-DiscordBot/cogs/remindme.py", line 108, in setup
    loop.create_task(n.check_reminders())
TypeError: check_reminders() missing 1 required positional argument: 'ctx'
[18/09/2017 00:43] ERROR owner load 73: check_reminders() missing 1 required positional argument: 'ctx'
Traceback (most recent call last):
  File "/home/peyrin/Desktop/Red-DiscordBot/cogs/owner.py", line 64, in load
    self._load_cog(module)
  File "/home/peyrin/Desktop/Red-DiscordBot/cogs/owner.py", line 947, in _load_cog
    self.bot.load_extension(mod_obj.__name__)
  File "lib/discord/ext/commands/bot.py", line 738, in load_extension
    lib.setup(self)
  File "/home/peyrin/Desktop/Red-DiscordBot/cogs/remindme.py", line 107, in setup
    loop.create_task(n.check_reminders())
TypeError: check_reminders() missing 1 required positional argument: 'ctx'
[18/09/2017 01:48] ERROR owner load 73: name 'General' is not defined
Traceback (most recent call last):
  File "/home/peyrin/Desktop/Red-DiscordBot/cogs/owner.py", line 64, in load
    self._load_cog(module)
  File "/home/peyrin/Desktop/Red-DiscordBot/cogs/owner.py", line 947, in _load_cog
    self.bot.load_extension(mod_obj.__name__)
  File "lib/discord/ext/commands/bot.py", line 738, in load_extension
    lib.setup(self)
  File "/home/peyrin/Desktop/Red-DiscordBot/cogs/goodchat.py", line 73, in setup
    n = General(bot)
NameError: name 'General' is not defined
[18/09/2017 01:49] ERROR owner load 73: object() takes no parameters
Traceback (most recent call last):
  File "/home/peyrin/Desktop/Red-DiscordBot/cogs/owner.py", line 64, in load
    self._load_cog(module)
  File "/home/peyrin/Desktop/Red-DiscordBot/cogs/owner.py", line 947, in _load_cog
    self.bot.load_extension(mod_obj.__name__)
  File "lib/discord/ext/commands/bot.py", line 738, in load_extension
    lib.setup(self)
  File "/home/peyrin/Desktop/Red-DiscordBot/cogs/goodchat.py", line 73, in setup
    n = Goodchat(bot)
TypeError: object() takes no parameters
[18/09/2017 02:45] ERROR red on_command_error 369: Exception in command 'customcom add'
Traceback (most recent call last):
  File "lib/discord/ext/commands/core.py", line 50, in wrapped
    ret = yield from coro(*args, **kwargs)
  File "/home/peyrin/Desktop/Red-DiscordBot/cogs/customcom.py", line 48, in cc_add
    command_list = deque(cmdlist[command])
NameError: name 'deque' is not defined
[18/09/2017 02:46] ERROR red on_command_error 369: Exception in command 'customcom add'
Traceback (most recent call last):
  File "lib/discord/ext/commands/core.py", line 50, in wrapped
    ret = yield from coro(*args, **kwargs)
  File "/home/peyrin/Desktop/Red-DiscordBot/cogs/customcom.py", line 50, in cc_add
    self.past_names[before.id] = list(names)
NameError: name 'names' is not defined
[18/09/2017 02:47] ERROR red on_command_error 369: Exception in command 'customcom add'
Traceback (most recent call last):
  File "lib/discord/ext/commands/core.py", line 50, in wrapped
    ret = yield from coro(*args, **kwargs)
  File "/home/peyrin/Desktop/Red-DiscordBot/cogs/customcom.py", line 50, in cc_add
    cmdlist[command] = list(names)
NameError: name 'names' is not defined
[18/09/2017 03:26] ERROR red load_cogs 573: name 'customcom' is not defined
Traceback (most recent call last):
  File "red.py", line 570, in load_cogs
    owner_cog._load_cog(extension)
  File "/home/peyrin/Desktop/Red-DiscordBot/cogs/owner.py", line 945, in _load_cog
    mod_obj = importlib.import_module(cogname)
  File "/home/peyrin/anaconda3/lib/python3.6/importlib/__init__.py", line 126, in import_module
    return _bootstrap._gcd_import(name[level:], package, level)
  File "<frozen importlib._bootstrap>", line 978, in _gcd_import
  File "<frozen importlib._bootstrap>", line 961, in _find_and_load
  File "<frozen importlib._bootstrap>", line 950, in _find_and_load_unlocked
  File "<frozen importlib._bootstrap>", line 655, in _load_unlocked
  File "<frozen importlib._bootstrap_external>", line 678, in exec_module
  File "<frozen importlib._bootstrap>", line 205, in _call_with_frames_removed
  File "/home/peyrin/Desktop/Red-DiscordBot/cogs/customcom.py", line 10, in <module>
    class CustomCommands:
  File "/home/peyrin/Desktop/Red-DiscordBot/cogs/customcom.py", line 111, in CustomCommands
    @customcom.command(name="list", pass_context=True)
NameError: name 'customcom' is not defined
[18/09/2017 03:35] ERROR red on_command_error 369: Exception in command 'remember'
Traceback (most recent call last):
  File "lib/discord/ext/commands/core.py", line 50, in wrapped
    ret = yield from coro(*args, **kwargs)
  File "/home/peyrin/Desktop/Red-DiscordBot/cogs/customcom.py", line 140, in cc_list
    if server.id in self.c_commands and self.bot.user_allowed(message):
NameError: name 'message' is not defined
[18/09/2017 03:36] ERROR red on_command_error 369: Exception in command 'remember'
Traceback (most recent call last):
  File "lib/discord/ext/commands/core.py", line 50, in wrapped
    ret = yield from coro(*args, **kwargs)
  File "/home/peyrin/Desktop/Red-DiscordBot/cogs/customcom.py", line 143, in cc_list
    command_list = list(cmdlist[cmd])
NameError: name 'cmd' is not defined
[18/09/2017 03:37] ERROR red on_command_error 369: Exception in command 'remember'
Traceback (most recent call last):
  File "lib/discord/ext/commands/core.py", line 50, in wrapped
    ret = yield from coro(*args, **kwargs)
  File "/home/peyrin/Desktop/Red-DiscordBot/cogs/customcom.py", line 145, in cc_list
    result = command_list[number]
TypeError: list indices must be integers or slices, not str
[18/09/2017 03:37] ERROR red on_command_error 369: Exception in command 'remember'
Traceback (most recent call last):
  File "lib/discord/ext/commands/core.py", line 50, in wrapped
    ret = yield from coro(*args, **kwargs)
  File "/home/peyrin/Desktop/Red-DiscordBot/cogs/customcom.py", line 149, in cc_list
    result = self.format_cc(result, message)
NameError: name 'message' is not defined
[18/09/2017 03:38] ERROR red on_command_error 369: Exception in command 'remember'
Traceback (most recent call last):
  File "lib/discord/ext/commands/core.py", line 50, in wrapped
    ret = yield from coro(*args, **kwargs)
  File "/home/peyrin/Desktop/Red-DiscordBot/cogs/customcom.py", line 150, in cc_list
    await self.bot.send_message(message.channel, result)
NameError: name 'message' is not defined
[18/09/2017 14:58] ERROR red on_command_error 369: Exception in command 'slot'
Traceback (most recent call last):
  File "lib/discord/ext/commands/core.py", line 50, in wrapped
    ret = yield from coro(*args, **kwargs)
  File "/home/peyrin/Desktop/Red-DiscordBot/cogs/economy.py", line 596, in slot
    await self.slot_machine(author, bid)
  File "/home/peyrin/Desktop/Red-DiscordBot/cogs/economy.py", line 649, in slot_machine
    self.bank.set_credits(author, now)
AttributeError: 'Bank' object has no attribute 'set_credits'
[18/09/2017 14:58] ERROR red on_command_error 369: Exception in command 'slot'
Traceback (most recent call last):
  File "lib/discord/ext/commands/core.py", line 50, in wrapped
    ret = yield from coro(*args, **kwargs)
  File "/home/peyrin/Desktop/Red-DiscordBot/cogs/economy.py", line 596, in slot
    await self.slot_machine(author, bid)
  File "/home/peyrin/Desktop/Red-DiscordBot/cogs/economy.py", line 649, in slot_machine
    self.bank.set_credits(author, now)
AttributeError: 'Bank' object has no attribute 'set_credits'
